Workbook

Sheet Raw_Data
A1: Customer_ID | B1: Customer_Name | C1: Age | D1: Region | E1: City | F1: Plan | G1: Acquisition_Channel | H1: Signup_Date | I1: Tenure_Months | J1: Contract_Type | K1: Payment_Method | L1: Monthly_Fee | M1: Support_Tickets | N1: Complaints | O1: Monthly_Usage_Hours | P1: Satisfaction_Score | Q1: Last_Login | R1: Churn_Date | S1: Churn_Status | T1: Primary_Product | U1: Duplicate_customer ID_Check
A2: C01310 | B2: Meera Das | D2: North | E2: Delhi | F2: Standard | G2: Instagram | H2: 45019 | I2: 9 | J2: Monthly | K2: UPI | L2: 1757 | M2: 2 | N2: 0 | O2: 32 | P2: 3.6 | Q2: 45308 | R2: 16/06/2023 | S2: Churned | T2: Cloud Storage | U2: =COUNTIF($A$2:$A$1826, A2) -> 1
A3: C00477 | B3: Rahul Das | C3: 40 | D3: North | E3: Jaipur | F3: Standard | G3: Facebook | H3: 45678 | I3: 27 | J3: Quarterly | K3: UPI | L3: 1283 | M3: 0 | N3: 2 | O3: 40.6 | P3: 4.4 | Q3: 45694 | S3: Active | T3: Cloud Storage | U3: =COUNTIF($A$2:$A$1826, A3) -> 1
A4: C01564 | B4: Priya Das | C4: 24 | D4: East | E4: Kolkata | F4: Basic | G4: Google Ads | H4: 45297 | I4: 23 | J4: Annual | K4: Credit Card | L4: 521 | M4: 2 | N4: 0 | O4: 14.3 | P4: 3.3 | Q4: 45856 | S4: Active | T4: Automation | U4: =COUNTIF($A$2:$A$1826, A4) -> 1
A5: C00741 | B5: Anita Patel | C5: 42 | D5: South | E5: Bengaluru | F5: Basic | G5: Instagram | H5: 45154 | I5: 6 | J5: Quarterly | K5: UPI | L5: 550 | M5: 1 | N5: 1 | O5: 9.9 | P5: 4 | Q5: 45280 | R5: 24/02/2024 | S5: Churned | T5: Collaboration | U5: =COUNTIF($A$2:$A$1826, A5) -> 1
A6: C01438 | B6: Anita Kumar | C6: 33 | D6: North | E6: Jaipur | F6: Standard | G6: Instagram | H6: 44896 | I6: 30 | J6: Monthly | K6: Credit Card | L6: 1703 | M6: 1 | N6: 1 | O6: 28.5 | P6: 2.4 | Q6: 45130 | S6: Active | T6: Security | U6: =COUNTIF($A$2:$A$1826, A6) -> 3
A7: C00549 | B7: Vikram Patel | C7: 34 | D7: North | E7: Jaipur | F7: Premium | G7: Organic Search | H7: 45206 | I7: 14 | J7: Annual | K7: Debit Card | L7: 2938 | M7: 2 | N7: 1 | O7: 33.2 | P7: 3.4 | Q7: 45289 | S7: Active | T7: Automation | U7: =COUNTIF($A$2:$A$1826, A7) -> 6
A8: C00539 | B8: Rahul Das | C8: 57 | D8: West | E8: Surat | F8: Basic | G8: Instagram | H8: 45605 | I8: 32 | J8: Monthly | K8: Credit Card | L8: ₹523 | M8: 2 | N8: 1 | O8: 16.2 | P8: 4.1 | Q8: 46257 | S8: Active | T8: Security | U8: =COUNTIF($A$2:$A$1826, A8) -> 2
A9: C01221 | B9: Anita Sharma | C9: 37 | D9: West | E9: Ahmedabad | F9: Premium | G9: YouTube | H9: 44585 | I9: 44 | J9: Quarterly | K9: UPI | L9: 3536 | M9: 0 | N9: 0 | O9: 43.9 | P9: 3.9 | Q9: 45141 | R9: 27/09/2025 | S9: Churned | T9: Security | U9: =COUNTIF($A$2:$A$1826, A9) -> 2
A10: C00007 | B10: Rahul Kumar | C10: 57 | D10: East | E10: Bhubaneswar | F10: Standard | G10: Google Ads | H10: 45842 | I10: 20 | J10: Quarterly | K10: Credit Card | L10: 1622 | M10: 1 | N10: 1 | O10: 27.1 | P10: 3.4 | Q10: 46008 | R10: 20/08/2026 | S10: Churned | T10: Analytics | U10: =COUNTIF($A$2:$A$1826, A10) -> 4
A11: C00230 | B11: Rahul Patel | C11: 61 | D11: East | E11: Patna | F11: Basic | G11: Instagram | H11: 45723 | I11: 6 | J11: Quarterly | K11: Debit Card | L11: 747 | M11: 1 | N11: 0 | O11: 20.7 | P11: 2.1 | Q11: 45869 | S11: Active | T11: Cloud Storage | U11: =COUNTIF($A$2:$A$1826, A11) -> 3
A12: C00543 | B12: Sneha Nair | C12: 26 | D12: West | E12: Pune | F12: Premium | G12: YouTube | H12: 45974 | I12: 13 | J12: Monthly | K12: UPI | L12: 3329 | M12: 2 | N12: 0 | O12: 42.7 | P12: 4.5 | Q12: 46175 | S12: Active | T12: Analytics | U12: =COUNTIF($A$2:$A$1826, A12) -> 5
A13: C00693 | B13: Anita Sharma | C13: 51 | D13: North | E13: Jaipur | F13: Standard | G13: Google Ads | H13: 44707 | I13: 46 | J13: Monthly | K13: Credit Card | L13: 1068 | M13: 0 | N13: 0 | O13: 15.9 | P13: 4.7 | Q13: 44781 | S13: Active | T13: Security | U13: =COUNTIF($A$2:$A$1826, A13) -> 3
A14: C00439 | B14: Karan Nair | C14: 65 | D14: South | E14: Kochi | F14: Basic | G14: Email | H14: 45395 | I14: 13 | J14: Monthly | K14: Debit Card | L14: 836 | M14: 3 | N14: 2 | O14: 27.4 | Q14: 45621 | S14: Active | T14: Analytics | U14: =COUNTIF($A$2:$A$1826, A14) -> 1
A15: C00125 | B15: Vikram Nair | C15: 34 | D15: West | E15: Ahmedabad | F15: Standard | G15: Google Ads | H15: 45071 | I15: 13 | J15: Monthly | K15: Credit Card | L15: ₹1,142 | M15: 2 | N15: 0 | O15: 27.7 | P15: 5 | Q15: 45174 | S15: Active | T15: Automation | U15: =COUNTIF($A$2:$A$1826, A15) -> 2
A16: C00201 | B16: Arun Patel | C16: 43 | D16: North | E16: Delhi | F16: Premium | G16: YouTube | H16: 45046 | I16: 11 | J16: Monthly | K16: Credit Card | L16: 3769 | M16: 3 | N16: 1 | O16: 38.7 | P16: 3.4 | Q16: 45261 | S16: Active | T16: Collaboration | U16: =COUNTIF($A$2:$A$1826, A16) -> 1
A17: C00932 | B17: Arun Kumar | C17: 66 | D17: East | E17: Guwahati | F17: Standard | G17: Facebook | H17: 45700 | I17: 43 | J17: Quarterly | K17: UPI | L17: 1193 | M17: 5 | N17: 3 | O17: 21.5 | P17: 3.2 | Q17: 46155 | S17: Active | T17: Analytics | U17: =COUNTIF($A$2:$A$1826, A17) -> 2
A18: C01197 | B18: Karan Sharma | C18: 55 | D18: West | E18: Pune | F18: Basic | G18: Organic Search | H18: 44726 | I18: 12 | J18: Monthly | K18: Debit Card | L18: 533 | M18: 1 | N18: 2 | O18: 12.4 | P18: 3.4 | Q18: 44856 | S18: Active | T18: Automation | U18: =COUNTIF($A$2:$A$1826, A18) -> 1
A19: C00082 | B19: Vikram Das | C19: 27 | D19: North | E19: Lucknow | F19: Standard | G19: Organic Search | H19: 45632 | I19: 21 | J19: Annual | K19: Debit Card | L19: 1684 | M19: 1 | N19: 0 | O19: 6.8 | P19: 4 | Q19: 45963 | R19: 06/09/2025 | S19: Churned | T19: Collaboration | U19: =COUNTIF($A$2:$A$1826, A19) -> 2
A20: C00937 | B20: Anita Sharma | C20: 34 | D20: East | E20: Kolkata | F20: Basic | G20: Organic Search | H20: 45715 | I20: 7 | J20: Quarterly | K20: Credit Card | L20: 608 | M20: 2 | N20: 2 | O20: 16.7 | P20: 4.1 | Q20: 45758 | S20: Active | T20: Cloud Storage | U20: =COUNTIF($A$2:$A$1826, A20) -> 1
A21: C00898 | B21: Ravi Patel | C21: 36 | D21: East | E21: Kolkata | F21: Standard | G21: Organic Search | H21: 45175 | I21: 43 | J21: MONTHLY | K21: Debit Card | L21: ₹1,269 | M21: 1 | N21: 1 | O21: 12.6 | P21: 3.7 | Q21: 45404 | S21: Active | T21: Cloud Storage | U21: =COUNTIF($A$2:$A$1826, A21) -> 1
A22: C01470 | B22: Vikram Kumar | C22: 19 | D22: East | E22: Bhubaneswar | F22: Standard | G22: YouTube | H22: 45102 | I22: 33 | J22: Quarterly | K22: UPI | L22: 1093 | M22: 1 | N22: 1 | O22: 26.5 | P22: 4 | Q22: 45545 | S22: Active | T22: Collaboration | U22: =COUNTIF($A$2:$A$1826, A22) -> 1
A23: C00331 | B23: Ravi Patel | C23: 46 | D23: West | E23: Surat | F23: Standard | G23: Google Ads | H23: 44716 | I23: 45 | J23: Monthly | K23: UPI | L23: 1035 | M23: 2 | N23: 2 | O23: 37.1 | P23: 4.4 | Q23: 45482 | R23: 08/10/2025 | S23: Churned | T23: Collaboration | U23: =COUNTIF($A$2:$A$1826, A23) -> 1
A24: C00747 | B24: Rahul Singh | C24: 29 | D24: North | E24: Chandigarh | F24: Basic | G24: Instagram | H24: 45927 | I24: 7 | J24: Monthly | K24: Credit Card | L24: 785 | M24: 0 | N24: 2 | O24: 10.1 | P24: 3.2 | Q24: 46095 | S24: Active | T24: Analytics | U24: =COUNTIF($A$2:$A$1826, A24) -> 1
A25: C00368 | B25: Sneha Singh | C25: 31 | D25: East | E25: Guwahati | F25: Standard | G25: YouTube | H25: 45070 | I25: 18 | J25: Quarterly | K25: Credit Card | L25: 1109 | M25: 1 | N25: 1 | O25: 15.6 | P25: 3.8 | Q25: 45119 | S25: Active | T25: Collaboration | U25: =COUNTIF($A$2:$A$1826, A25) -> 2
A26: C00467 | B26: Ravi Reddy | C26: 20 | D26: South | E26: Bengaluru | F26: Standard | G26: Email | H26: 45234 | I26: 18 | J26: Monthly | K26: Credit Card | L26: 1284 | M26: 4 | N26: 1 | O26: 21.7 | P26: 3.4 | Q26: 45765 | R26: 16/01/2025 | S26: Churned | T26: Cloud Storage | U26: =COUNTIF($A$2:$A$1826, A26) -> 2
A27: C01190 | B27: Meera Singh | C27: 35 | D27: East | E27: Kolkata | F27: Basic | G27: Email | H27: 45269 | I27: 47 | J27: Monthly | K27: Debit Card | L27: 722 | N27: 4 | O27: 15.4 | P27: 3.5 | Q27: 45515 | R27: 06/03/2026 | S27: Churned | T27: Security | U27: =COUNTIF($A$2:$A$1826, A27) -> 3
A28: C00004 | B28: Ravi Iyer | C28: 61 | D28: South | E28: Hyderabad | F28: Basic | G28: Facebook | H28: 45238 | I28: 40 | J28: Quarterly | K28: Credit Card | L28: 562 | M28: 0 | N28: 0 | O28: 19.8 | P28: 4.5 | Q28: 45863 | S28: Active | T28: Security | U28: =COUNTIF($A$2:$A$1826, A28) -> 1
A29: C01428 | B29: Ravi Kumar | C29: 38 | D29: East | E29: Bhubaneswar | F29: Basic | G29: Facebook | H29: 45338 | I29: 44 | J29: Quarterly | K29: UPI | L29: 588 | M29: 2 | N29: 1 | O29: 19.4 | P29: 2.6 | Q29: 45964 | R29: 26/06/2026 | S29: Churned | T29: Security | U29: =COUNTIF($A$2:$A$1826, A29) -> 2
A30: C01188 | B30: Vikram Reddy | C30: 24 | D30: East | E30: Guwahati | F30: Basic | G30: Facebook | H30: 44999 | I30: 33 | J30: Quarterly | K30: Debit Card | L30: 875 | M30: 4 | N30: 0 | O30: 27.3 | P30: 3 | Q30: 45095 | S30: Active | T30: Collaboration | U30: =COUNTIF($A$2:$A$1826, A30) -> 2
A31: C00461 | B31: Karan Nair | C31: 44 | D31: South | E31: Chennai | F31: Basic | G31: Instagram | H31: 45535 | I31: 40 | J31: Monthly | K31: UPI | L31: 536 | M31: 5 | N31: 1 | O31: 10.9 | P31: 3 | Q31: 46723 | R31: 02/11/2025 | S31: Churned | T31: Analytics | U31: =COUNTIF($A$2:$A$1826, A31) -> 2
A32: C01538 | B32: Sneha Patel | C32: 48 | D32: North | E32: Lucknow | F32: Basic | G32: YouTube | H32: 45987 | I32: 34 | J32: Annual | K32: Debit Card | L32: 784 | M32: 1 | N32: 1 | O32: 23 | P32: 2.9 | Q32: 46245 | S32: Active | T32: Automation | U32: =COUNTIF($A$2:$A$1826, A32) -> 1
A33: C01220 | B33: Sneha Nair | C33: 35 | D33: East | E33: Guwahati | F33: standard | G33: Facebook | H33: 45595 | I33: 28 | J33: Monthly | K33: Debit Card | L33: 1455 | M33: 0 | N33: 4 | O33: 26.2 | P33: 4.3 | Q33: 45767 | R33: 30/12/2026 | S33: Churned | T33: Collaboration | U33: =COUNTIF($A$2:$A$1826, A33) -> 3
A34: C01569 | B34: Rahul Singh | C34: 43 | D34: West | E34: Pune | F34: Basic | G34: Google Ads | H34: 45147 | I34: 16 | J34: Annual | K34: UPI | L34: 662 | M34: 2 | N34: 2 | O34: 11.2 | P34: 2.3 | Q34: 45227 | S34: Active | T34: Cloud Storage | U34: =COUNTIF($A$2:$A$1826, A34) -> 4
A35: C00132 | B35: Meera Das | C35: 49 | D35: West | E35: Surat | F35: Basic | G35: Email | H35: 45413 | I35: 4 | J35: Monthly | K35: Credit Card | L35: 714 | M35: 2 | N35: 2 | O35: 10.9 | P35: 3.8 | Q35: 45428 | S35: Active | T35: Collaboration | U35: =COUNTIF($A$2:$A$1826, A35) -> 2
A36: C01544 | B36: Arun Das | C36: 40 | D36: West | E36: Surat | F36: Standard | G36: Facebook | H36: 45680 | I36: 39 | J36: Annual | K36: Debit Card | L36: 1223 | M36: 1 | N36: 4 | O36: 36.7 | P36: 4.6 | Q36: 46582 | R36: 13/11/2027 | S36: Churned | T36: Security | U36: =COUNTIF($A$2:$A$1826, A36) -> 2
A37: C01484 | B37: Karan Patel | C37: 48 | D37: South | E37: Kochi | F37: Premium | G37: Organic Search | H37: 45655 | I37: 2 | J37: Monthly | K37: UPI | L37: 3356 | M37: 4 | N37: 1 | O37: 49.5 | P37: 3.7 | Q37: 45668 | R37: 02/02/2025 | S37: Churned | T37: Collaboration | U37: =COUNTIF($A$2:$A$1826, A37) -> 2
A38: C00777 | B38: Arun Kumar | C38: 41 | D38: East | E38: Bhubaneswar | F38: Standard | G38: Referral | H38: 45338 | I38: 18 | J38: Monthly | K38: Debit Card | L38: 1257 | M38: 2 | N38: 1 | O38: 24.1 | P38: 3.8 | Q38: 45431 | R38: 11/07/2025 | S38: Churned | T38: Analytics | U38: =COUNTIF($A$2:$A$1826, A38) -> 2
A39: C01600 | B39: Meera Singh | C39: 48 | D39: North | E39: Delhi | F39: Premium | G39: Instagram | H39: 44603 | I39: 40 | J39: Annual | K39: Credit Card | L39: 3370 | M39: 2 | N39: 1 | O39: 30.9 | P39: 3.4 | Q39: 44847 | S39: Active | T39: Collaboration | U39: =COUNTIF($A$2:$A$1826, A39) -> 1
A40: C00344 | B40: Neha Sharma | C40: 56 | D40: North | E40: Jaipur | F40: Premium | G40: Google Ads | H40: 45747 | I40: 2 | J40: Annual | K40: Debit Card | L40: 3858 | M40: 4 | N40: 0 | O40: 38.4 | P40: 3.1 | Q40: 45805 | R40: 25/05/2025 | S40: churned | T40: Cloud Storage | U40: =COUNTIF($A$2:$A$1826, A40) -> 2
...

Sheet Processed_Data
A1: Customer_ID | B1: Customer_Name | C1: Age | D1: Region | E1: City | F1: Plan | G1: Acquisition_Channel | H1: Signup_Date | I1: Tenure_Months | J1: Contract_Type | K1: Payment_Method | L1: Monthly_Fee | M1: Support_Tickets | N1: Complaints | O1: Monthly_Usage_Hours | P1: Satisfaction_Score | Q1: Last_Login | R1: Churn_Date | S1: Churn_Status | T1: Primary_Product | U1: Temporary Customer_ID
A2: C01310 | B2: Meera Das | D2: North | E2: Delhi | F2: Standard | G2: Instagram | H2: 45019 | I2: 9 | J2: Monthly | K2: Upi | L2: 1757 | M2: 2 | N2: 0 | O2: 32 | P2: 3.6 | Q2: 45308 | R2: 16/06/2023 | S2: Churned | T2: Cloud Storage | U2: =COUNTIF($A$2:$A$1826, A2) -> 1 | V2: =TEXTJOIN("|",FALSE, A2:T2) -> C01310|Meera Das||North|Delhi|Standard|Instagram|4/3/2023|9|Monthly|Upi|1,757|2|0|32.00|3.6|1/17/2024|16/06/2023|Churned|Cloud Storage | W2: =COUNTIF($V$2:$V$1826, V2) -> 1 | X2: =IFERROR(__xludf.DUMMYFUNCTION("COUNTUNIQUE(FILTER($B$2:$B$1826,$A$2:$A$1826=A2))"),1.0) -> 1
A3: C00477 | B3: Rahul Das | C3: 40 | D3: North | E3: Jaipur | F3: Standard | G3: Facebook | H3: 45678 | I3: 27 | J3: Quarterly | K3: Upi | L3: 1283 | M3: 0 | N3: 2 | O3: 40.6 | P3: 4.4 | Q3: 45694 | S3: Active | T3: Cloud Storage | U3: =COUNTIF($A$2:$A$1826, A3) -> 1 | V3: =TEXTJOIN("|",FALSE, A3:T3) -> C00477|Rahul Das|40|North|Jaipur|Standard|Facebook|1/21/2025|27|Quarterly|Upi|1,283|0|2|40.60|4.4|2/6/2025||Active|Cloud Storage | W3: =COUNTIF($V$2:$V$1826, V3) -> 1 | X3: =IFERROR(__xludf.DUMMYFUNCTION("COUNTUNIQUE(FILTER($B$2:$B$1826,$A$2:$A$1826=A3))"),1.0) -> 1
A4: C01564 | B4: Priya Das | C4: 24 | D4: East | E4: Kolkata | F4: Basic | G4: Google Ads | H4: 45297 | I4: 23 | J4: Annual | K4: Credit Card | L4: 521 | M4: 2 | N4: 0 | O4: 14.3 | P4: 3.3 | Q4: 45856 | S4: Active | T4: Automation | U4: =COUNTIF($A$2:$A$1826, A4) -> 1 | V4: =TEXTJOIN("|",FALSE, A4:T4) -> C01564|Priya Das|24|East|Kolkata|Basic|Google Ads|1/6/2024|23|Annual|Credit Card|521|2|0|14.30|3.3|7/18/2025||Active|Automation | W4: =COUNTIF($V$2:$V$1826, V4) -> 1 | X4: =IFERROR(__xludf.DUMMYFUNCTION("COUNTUNIQUE(FILTER($B$2:$B$1826,$A$2:$A$1826=A4))"),1.0) -> 1
A5: C00741 | B5: Anita Patel | C5: 42 | D5: South | E5: Bengaluru | F5: Basic | G5: Instagram | H5: 45154 | I5: 6 | J5: Quarterly | K5: Upi | L5: 550 | M5: 1 | N5: 1 | O5: 9.9 | P5: 4 | Q5: 45280 | R5: 24/02/2024 | S5: Churned | T5: Collaboration | U5: =COUNTIF($A$2:$A$1826, A5) -> 1 | V5: =TEXTJOIN("|",FALSE, A5:T5) -> C00741|Anita Patel|42|South|Bengaluru|Basic|Instagram|8/16/2023|6|Quarterly|Upi|550|1|1|9.90|4|12/20/2023|24/02/2024|Churned|Collaboration | W5: =COUNTIF($V$2:$V$1826, V5) -> 1 | X5: =IFERROR(__xludf.DUMMYFUNCTION("COUNTUNIQUE(FILTER($B$2:$B$1826,$A$2:$A$1826=A5))"),1.0) -> 1
A6: C01438 | B6: Anita Kumar | C6: 33 | D6: North | E6: Jaipur | F6: Standard | G6: Instagram | H6: 44896 | I6: 30 | J6: Monthly | K6: Credit Card | L6: 1703 | M6: 1 | N6: 1 | O6: 28.5 | P6: 2.4 | Q6: 45130 | S6: Active | T6: Security | U6: =COUNTIF($A$2:$A$1826, A6) -> 3 | V6: =TEXTJOIN("|",FALSE, A6:T6) -> C01438|Anita Kumar|33|North|Jaipur|Standard|Instagram|12/1/2022|30|Monthly|Credit Card|1,703|1|1|28.50|2.4|7/23/2023||Active|Security | W6: =COUNTIF($V$2:$V$1826, V6) -> 1 | X6: =IFERROR(__xludf.DUMMYFUNCTION("COUNTUNIQUE(FILTER($B$2:$B$1826,$A$2:$A$1826=A6))"),3.0) -> 3
A7: C00549 | B7: Vikram Patel | C7: 34 | D7: North | E7: Jaipur | F7: Premium | G7: Organic Search | H7: 45206 | I7: 14 | J7: Annual | K7: Debit Card | L7: 2938 | M7: 2 | N7: 1 | O7: 33.2 | P7: 3.4 | Q7: 45289 | S7: Active | T7: Automation | U7: =COUNTIF($A$2:$A$1826, A7) -> 6 | V7: =TEXTJOIN("|",FALSE, A7:T7) -> C00549|Vikram Patel|34|North|Jaipur|Premium|Organic Search|10/7/2023|14|Annual|Debit Card|2,938|2|1|33.20|3.4|12/29/2023||Active|Automation | W7: =COUNTIF($V$2:$V$1826, V7) -> 1 | X7: =IFERROR(__xludf.DUMMYFUNCTION("COUNTUNIQUE(FILTER($B$2:$B$1826,$A$2:$A$1826=A7))"),6.0) -> 6
A8: C00539 | B8: Rahul Das | C8: 57 | D8: West | E8: Surat | F8: Basic | G8: Instagram | H8: 45605 | I8: 32 | J8: Monthly | K8: Credit Card | L8: 523 | M8: 2 | N8: 1 | O8: 16.2 | P8: 4.1 | Q8: 46257 | S8: Active | T8: Security | U8: =COUNTIF($A$2:$A$1826, A8) -> 2 | V8: =TEXTJOIN("|",FALSE, A8:T8) -> C00539|Rahul Das|57|West|Surat|Basic|Instagram|11/9/2024|32|Monthly|Credit Card|523|2|1|16.20|4.1|8/23/2026||Active|Security | W8: =COUNTIF($V$2:$V$1826, V8) -> 1 | X8: =IFERROR(__xludf.DUMMYFUNCTION("COUNTUNIQUE(FILTER($B$2:$B$1826,$A$2:$A$1826=A8))"),2.0) -> 2
A9: C01221 | B9: Anita Sharma | C9: 37 | D9: West | E9: Ahmedabad | F9: Premium | G9: Youtube | H9: 44585 | I9: 44 | J9: Quarterly | K9: Upi | L9: 3536 | M9: 0 | N9: 0 | O9: 43.9 | P9: 3.9 | Q9: 45141 | R9: 27/09/2025 | S9: Churned | T9: Security | U9: =COUNTIF($A$2:$A$1826, A9) -> 2 | V9: =TEXTJOIN("|",FALSE, A9:T9) -> C01221|Anita Sharma|37|West|Ahmedabad|Premium|Youtube|1/24/2022|44|Quarterly|Upi|3,536|0|0|43.90|3.9|8/3/2023|27/09/2025|Churned|Security | W9: =COUNTIF($V$2:$V$1826, V9) -> 1 | X9: =IFERROR(__xludf.DUMMYFUNCTION("COUNTUNIQUE(FILTER($B$2:$B$1826,$A$2:$A$1826=A9))"),2.0) -> 2
A10: C00007 | B10: Rahul Kumar | C10: 57 | D10: East | E10: Bhubaneswar | F10: Standard | G10: Google Ads | H10: 45842 | I10: 20 | J10: Quarterly | K10: Credit Card | L10: 1622 | M10: 1 | N10: 1 | O10: 27.1 | P10: 3.4 | Q10: 46008 | R10: 20/08/2026 | S10: Churned | T10: Analytics | U10: =COUNTIF($A$2:$A$1826, A10) -> 4 | V10: =TEXTJOIN("|",FALSE, A10:T10) -> C00007|Rahul Kumar|57|East|Bhubaneswar|Standard|Google Ads|7/4/2025|20|Quarterly|Credit Card|1,622|1|1|27.10|3.4|12/17/2025|20/08/2026|Churned|Analytics | W10: =COUNTIF($V$2:$V$1826, V10) -> 1 | X10: =IFERROR(__xludf.DUMMYFUNCTION("COUNTUNIQUE(FILTER($B$2:$B$1826,$A$2:$A$1826=A10))"),4.0) -> 4
A11: C00230 | B11: Rahul Patel | C11: 61 | D11: East | E11: Patna | F11: Basic | G11: Instagram | H11: 45723 | I11: 6 | J11: Quarterly | K11: Debit Card | L11: 747 | M11: 1 | N11: 0 | O11: 20.7 | P11: 2.1 | Q11: 45869 | S11: Active | T11: Cloud Storage | U11: =COUNTIF($A$2:$A$1826, A11) -> 3 | V11: =TEXTJOIN("|",FALSE, A11:T11) -> C00230|Rahul Patel|61|East|Patna|Basic|Instagram|3/7/2025|6|Quarterly|Debit Card|747|1|0|20.70|2.1|7/31/2025||Active|Cloud Storage | W11: =COUNTIF($V$2:$V$1826, V11) -> 1 | X11: =IFERROR(__xludf.DUMMYFUNCTION("COUNTUNIQUE(FILTER($B$2:$B$1826,$A$2:$A$1826=A11))"),3.0) -> 3
A12: C00543 | B12: Sneha Nair | C12: 26 | D12: West | E12: Pune | F12: Premium | G12: Youtube | H12: 45974 | I12: 13 | J12: Monthly | K12: Upi | L12: 3329 | M12: 2 | N12: 0 | O12: 42.7 | P12: 4.5 | Q12: 46175 | S12: Active | T12: Analytics | U12: =COUNTIF($A$2:$A$1826, A12) -> 5 | V12: =TEXTJOIN("|",FALSE, A12:T12) -> C00543|Sneha Nair|26|West|Pune|Premium|Youtube|11/13/2025|13|Monthly|Upi|3,329|2|0|42.70|4.5|6/2/2026||Active|Analytics | W12: =COUNTIF($V$2:$V$1826, V12) -> 1 | X12: =IFERROR(__xludf.DUMMYFUNCTION("COUNTUNIQUE(FILTER($B$2:$B$1826,$A$2:$A$1826=A12))"),5.0) -> 5
A13: C00693 | B13: Anita Sharma | C13: 51 | D13: North | E13: Jaipur | F13: Standard | G13: Google Ads | H13: 44707 | I13: 46 | J13: Monthly | K13: Credit Card | L13: 1068 | M13: 0 | N13: 0 | O13: 15.9 | P13: 4.7 | Q13: 44781 | S13: Active | T13: Security | U13: =COUNTIF($A$2:$A$1826, A13) -> 3 | V13: =TEXTJOIN("|",FALSE, A13:T13) -> C00693|Anita Sharma|51|North|Jaipur|Standard|Google Ads|5/26/2022|46|Monthly|Credit Card|1,068|0|0|15.90|4.7|8/8/2022||Active|Security | W13: =COUNTIF($V$2:$V$1826, V13) -> 1 | X13: =IFERROR(__xludf.DUMMYFUNCTION("COUNTUNIQUE(FILTER($B$2:$B$1826,$A$2:$A$1826=A13))"),3.0) -> 3
A14: C00439 | B14: Karan Nair | C14: 65 | D14: South | E14: Kochi | F14: Basic | G14: Email | H14: 45395 | I14: 13 | J14: Monthly | K14: Debit Card | L14: 836 | M14: 3 | N14: 2 | O14: 27.4 | Q14: 45621 | S14: Active | T14: Analytics | U14: =COUNTIF($A$2:$A$1826, A14) -> 1 | V14: =TEXTJOIN("|",FALSE, A14:T14) -> C00439|Karan Nair|65|South|Kochi|Basic|Email|4/13/2024|13|Monthly|Debit Card|836|3|2|27.40||11/25/2024||Active|Analytics | W14: =COUNTIF($V$2:$V$1826, V14) -> 1 | X14: =IFERROR(__xludf.DUMMYFUNCTION("COUNTUNIQUE(FILTER($B$2:$B$1826,$A$2:$A$1826=A14))"),1.0) -> 1
A15: C00125 | B15: Vikram Nair | C15: 34 | D15: West | E15: Ahmedabad | F15: Standard | G15: Google Ads | H15: 45071 | I15: 13 | J15: Monthly | K15: Credit Card | L15: 1142 | M15: 2 | N15: 0 | O15: 27.7 | P15: 5 | Q15: 45174 | S15: Active | T15: Automation | U15: =COUNTIF($A$2:$A$1826, A15) -> 2 | V15: =TEXTJOIN("|",FALSE, A15:T15) -> C00125|Vikram Nair|34|West|Ahmedabad|Standard|Google Ads|5/25/2023|13|Monthly|Credit Card|1,142|2|0|27.70|5|9/5/2023||Active|Automation | W15: =COUNTIF($V$2:$V$1826, V15) -> 1 | X15: =IFERROR(__xludf.DUMMYFUNCTION("COUNTUNIQUE(FILTER($B$2:$B$1826,$A$2:$A$1826=A15))"),2.0) -> 2
A16: C00201 | B16: Arun Patel | C16: 43 | D16: North | E16: Delhi | F16: Premium | G16: Youtube | H16: 45046 | I16: 11 | J16: Monthly | K16: Credit Card | L16: 3769 | M16: 3 | N16: 1 | O16: 38.7 | P16: 3.4 | Q16: 45261 | S16: Active | T16: Collaboration | U16: =COUNTIF($A$2:$A$1826, A16) -> 1 | V16: =TEXTJOIN("|",FALSE, A16:T16) -> C00201|Arun Patel|43|North|Delhi|Premium|Youtube|4/30/2023|11|Monthly|Credit Card|3,769|3|1|38.70|3.4|12/1/2023||Active|Collaboration | W16: =COUNTIF($V$2:$V$1826, V16) -> 1 | X16: =IFERROR(__xludf.DUMMYFUNCTION("COUNTUNIQUE(FILTER($B$2:$B$1826,$A$2:$A$1826=A16))"),1.0) -> 1
A17: C00932 | B17: Arun Kumar | C17: 66 | D17: East | E17: Guwahati | F17: Standard | G17: Facebook | H17: 45700 | I17: 43 | J17: Quarterly | K17: Upi | L17: 1193 | M17: 5 | N17: 3 | O17: 21.5 | P17: 3.2 | Q17: 46155 | S17: Active | T17: Analytics | U17: =COUNTIF($A$2:$A$1826, A17) -> 2 | V17: =TEXTJOIN("|",FALSE, A17:T17) -> C00932|Arun Kumar|66|East|Guwahati|Standard|Facebook|2/12/2025|43|Quarterly|Upi|1,193|5|3|21.50|3.2|5/13/2026||Active|Analytics | W17: =COUNTIF($V$2:$V$1826, V17) -> 1 | X17: =IFERROR(__xludf.DUMMYFUNCTION("COUNTUNIQUE(FILTER($B$2:$B$1826,$A$2:$A$1826=A17))"),2.0) -> 2
A18: C01197 | B18: Karan Sharma | C18: 55 | D18: West | E18: Pune | F18: Basic | G18: Organic Search | H18: 44726 | I18: 12 | J18: Monthly | K18: Debit Card | L18: 533 | M18: 1 | N18: 2 | O18: 12.4 | P18: 3.4 | Q18: 44856 | S18: Active | T18: Automation | U18: =COUNTIF($A$2:$A$1826, A18) -> 1 | V18: =TEXTJOIN("|",FALSE, A18:T18) -> C01197|Karan Sharma|55|West|Pune|Basic|Organic Search|6/14/2022|12|Monthly|Debit Card|533|1|2|12.40|3.4|10/22/2022||Active|Automation | W18: =COUNTIF($V$2:$V$1826, V18) -> 1 | X18: =IFERROR(__xludf.DUMMYFUNCTION("COUNTUNIQUE(FILTER($B$2:$B$1826,$A$2:$A$1826=A18))"),1.0) -> 1
A19: C00082 | B19: Vikram Das | C19: 27 | D19: North | E19: Lucknow | F19: Standard | G19: Organic Search | H19: 45632 | I19: 21 | J19: Annual | K19: Debit Card | L19: 1684 | M19: 1 | N19: 0 | O19: 6.8 | P19: 4 | Q19: 45963 | R19: 45817 | S19: Churned | T19: Collaboration | U19: =COUNTIF($A$2:$A$1826, A19) -> 2 | V19: =TEXTJOIN("|",FALSE, A19:T19) -> C00082|Vikram Das|27|North|Lucknow|Standard|Organic Search|12/6/2024|21|Annual|Debit Card|1,684|1|0|6.80|4|11/2/2025|6/9/2025|Churned|Collaboration | W19: =COUNTIF($V$2:$V$1826, V19) -> 1 | X19: =IFERROR(__xludf.DUMMYFUNCTION("COUNTUNIQUE(FILTER($B$2:$B$1826,$A$2:$A$1826=A19))"),2.0) -> 2
A20: C00937 | B20: Anita Sharma | C20: 34 | D20: East | E20: Kolkata | F20: Basic | G20: Organic Search | H20: 45715 | I20: 7 | J20: Quarterly | K20: Credit Card | L20: 608 | M20: 2 | N20: 2 | O20: 16.7 | P20: 4.1 | Q20: 45758 | S20: Active | T20: Cloud Storage | U20: =COUNTIF($A$2:$A$1826, A20) -> 1 | V20: =TEXTJOIN("|",FALSE, A20:T20) -> C00937|Anita Sharma|34|East|Kolkata|Basic|Organic Search|2/27/2025|7|Quarterly|Credit Card|608|2|2|16.70|4.1|4/11/2025||Active|Cloud Storage | W20: =COUNTIF($V$2:$V$1826, V20) -> 1 | X20: =IFERROR(__xludf.DUMMYFUNCTION("COUNTUNIQUE(FILTER($B$2:$B$1826,$A$2:$A$1826=A20))"),1.0) -> 1
A21: C00898 | B21: Ravi Patel | C21: 36 | D21: East | E21: Kolkata | F21: Standard | G21: Organic Search | H21: 45175 | I21: 43 | J21: Monthly | K21: Debit Card | L21: 1269 | M21: 1 | N21: 1 | O21: 12.6 | P21: 3.7 | Q21: 45404 | S21: Active | T21: Cloud Storage | U21: =COUNTIF($A$2:$A$1826, A21) -> 1 | V21: =TEXTJOIN("|",FALSE, A21:T21) -> C00898|Ravi Patel|36|East|Kolkata|Standard|Organic Search|9/6/2023|43|Monthly|Debit Card|1,269|1|1|12.60|3.7|4/22/2024||Active|Cloud Storage | W21: =COUNTIF($V$2:$V$1826, V21) -> 1 | X21: =IFERROR(__xludf.DUMMYFUNCTION("COUNTUNIQUE(FILTER($B$2:$B$1826,$A$2:$A$1826=A21))"),1.0) -> 1
A22: C01470 | B22: Vikram Kumar | C22: 19 | D22: East | E22: Bhubaneswar | F22: Standard | G22: Youtube | H22: 45102 | I22: 33 | J22: Quarterly | K22: Upi | L22: 1093 | M22: 1 | N22: 1 | O22: 26.5 | P22: 4 | Q22: 45545 | S22: Active | T22: Collaboration | U22: =COUNTIF($A$2:$A$1826, A22) -> 1 | V22: =TEXTJOIN("|",FALSE, A22:T22) -> C01470|Vikram Kumar|19|East|Bhubaneswar|Standard|Youtube|6/25/2023|33|Quarterly|Upi|1,093|1|1|26.50|4|9/10/2024||Active|Collaboration | W22: =COUNTIF($V$2:$V$1826, V22) -> 1 | X22: =IFERROR(__xludf.DUMMYFUNCTION("COUNTUNIQUE(FILTER($B$2:$B$1826,$A$2:$A$1826=A22))"),1.0) -> 1
A23: C00331 | B23: Ravi Patel | C23: 46 | D23: West | E23: Surat | F23: Standard | G23: Google Ads | H23: 44716 | I23: 45 | J23: Monthly | K23: Upi | L23: 1035 | M23: 2 | N23: 2 | O23: 37.1 | P23: 4.4 | Q23: 45482 | R23: 45879 | S23: Churned | T23: Collaboration | U23: =COUNTIF($A$2:$A$1826, A23) -> 1 | V23: =TEXTJOIN("|",FALSE, A23:T23) -> C00331|Ravi Patel|46|West|Surat|Standard|Google Ads|6/4/2022|45|Monthly|Upi|1,035|2|2|37.10|4.4|7/9/2024|8/10/2025|Churned|Collaboration | W23: =COUNTIF($V$2:$V$1826, V23) -> 1 | X23: =IFERROR(__xludf.DUMMYFUNCTION("COUNTUNIQUE(FILTER($B$2:$B$1826,$A$2:$A$1826=A23))"),1.0) -> 1
A24: C00747 | B24: Rahul Singh | C24: 29 | D24: North | E24: Chandigarh | F24: Basic | G24: Instagram | H24: 45927 | I24: 7 | J24: Monthly | K24: Credit Card | L24: 785 | M24: 0 | N24: 2 | O24: 10.1 | P24: 3.2 | Q24: 46095 | S24: Active | T24: Analytics | U24: =COUNTIF($A$2:$A$1826, A24) -> 1 | V24: =TEXTJOIN("|",FALSE, A24:T24) -> C00747|Rahul Singh|29|North|Chandigarh|Basic|Instagram|9/27/2025|7|Monthly|Credit Card|785|0|2|10.10|3.2|3/14/2026||Active|Analytics | W24: =COUNTIF($V$2:$V$1826, V24) -> 1 | X24: =IFERROR(__xludf.DUMMYFUNCTION("COUNTUNIQUE(FILTER($B$2:$B$1826,$A$2:$A$1826=A24))"),1.0) -> 1
A25: C00368 | B25: Sneha Singh | C25: 31 | D25: East | E25: Guwahati | F25: Standard | G25: Youtube | H25: 45070 | I25: 18 | J25: Quarterly | K25: Credit Card | L25: 1109 | M25: 1 | N25: 1 | O25: 15.6 | P25: 3.8 | Q25: 45119 | S25: Active | T25: Collaboration | U25: =COUNTIF($A$2:$A$1826, A25) -> 2 | V25: =TEXTJOIN("|",FALSE, A25:T25) -> C00368|Sneha Singh|31|East|Guwahati|Standard|Youtube|5/24/2023|18|Quarterly|Credit Card|1,109|1|1|15.60|3.8|7/12/2023||Active|Collaboration | W25: =COUNTIF($V$2:$V$1826, V25) -> 1 | X25: =IFERROR(__xludf.DUMMYFUNCTION("COUNTUNIQUE(FILTER($B$2:$B$1826,$A$2:$A$1826=A25))"),2.0) -> 2
A26: C00467 | B26: Ravi Reddy | C26: 20 | D26: South | E26: Bengaluru | F26: Standard | G26: Email | H26: 45234 | I26: 18 | J26: Monthly | K26: Credit Card | L26: 1284 | M26: 4 | N26: 1 | O26: 21.7 | P26: 3.4 | Q26: 45765 | R26: 16/01/2025 | S26: Churned | T26: Cloud Storage | U26: =COUNTIF($A$2:$A$1826, A26) -> 2 | V26: =TEXTJOIN("|",FALSE, A26:T26) -> C00467|Ravi Reddy|20|South|Bengaluru|Standard|Email|11/4/2023|18|Monthly|Credit Card|1,284|4|1|21.70|3.4|4/18/2025|16/01/2025|Churned|Cloud Storage | W26: =COUNTIF($V$2:$V$1826, V26) -> 1 | X26: =IFERROR(__xludf.DUMMYFUNCTION("COUNTUNIQUE(FILTER($B$2:$B$1826,$A$2:$A$1826=A26))"),2.0) -> 2
A27: C01190 | B27: Meera Singh | C27: 35 | D27: East | E27: Kolkata | F27: Basic | G27: Email | H27: 45269 | I27: 47 | J27: Monthly | K27: Debit Card | L27: 722 | N27: 4 | O27: 15.4 | P27: 3.5 | Q27: 45515 | R27: 46176 | S27: Churned | T27: Security | U27: =COUNTIF($A$2:$A$1826, A27) -> 3 | V27: =TEXTJOIN("|",FALSE, A27:T27) -> C01190|Meera Singh|35|East|Kolkata|Basic|Email|12/9/2023|47|Monthly|Debit Card|722||4|15.40|3.5|8/11/2024|6/3/2026|Churned|Security | W27: =COUNTIF($V$2:$V$1826, V27) -> 1 | X27: =IFERROR(__xludf.DUMMYFUNCTION("COUNTUNIQUE(FILTER($B$2:$B$1826,$A$2:$A$1826=A27))"),3.0) -> 3
A28: C00004 | B28: Ravi Iyer | C28: 61 | D28: South | E28: Hyderabad | F28: Basic | G28: Facebook | H28: 45238 | I28: 40 | J28: Quarterly | K28: Credit Card | L28: 562 | M28: 0 | N28: 0 | O28: 19.8 | P28: 4.5 | Q28: 45863 | S28: Active | T28: Security | U28: =COUNTIF($A$2:$A$1826, A28) -> 1 | V28: =TEXTJOIN("|",FALSE, A28:T28) -> C00004|Ravi Iyer|61|South|Hyderabad|Basic|Facebook|11/8/2023|40|Quarterly|Credit Card|562|0|0|19.80|4.5|7/25/2025||Active|Security | W28: =COUNTIF($V$2:$V$1826, V28) -> 1 | X28: =IFERROR(__xludf.DUMMYFUNCTION("COUNTUNIQUE(FILTER($B$2:$B$1826,$A$2:$A$1826=A28))"),1.0) -> 1
A29: C01428 | B29: Ravi Kumar | C29: 38 | D29: East | E29: Bhubaneswar | F29: Basic | G29: Facebook | H29: 45338 | I29: 44 | J29: Quarterly | K29: Upi | L29: 588 | M29: 2 | N29: 1 | O29: 19.4 | P29: 2.6 | Q29: 45964 | R29: 26/06/2026 | S29: Churned | T29: Security | U29: =COUNTIF($A$2:$A$1826, A29) -> 2 | V29: =TEXTJOIN("|",FALSE, A29:T29) -> C01428|Ravi Kumar|38|East|Bhubaneswar|Basic|Facebook|2/16/2024|44|Quarterly|Upi|588|2|1|19.40|2.6|11/3/2025|26/06/2026|Churned|Security | W29: =COUNTIF($V$2:$V$1826, V29) -> 1 | X29: =IFERROR(__xludf.DUMMYFUNCTION("COUNTUNIQUE(FILTER($B$2:$B$1826,$A$2:$A$1826=A29))"),2.0) -> 2
A30: C01188 | B30: Vikram Reddy | C30: 24 | D30: East | E30: Guwahati | F30: Basic | G30: Facebook | H30: 44999 | I30: 33 | J30: Quarterly | K30: Debit Card | L30: 875 | M30: 4 | N30: 0 | O30: 27.3 | P30: 3 | Q30: 45095 | S30: Active | T30: Collaboration | U30: =COUNTIF($A$2:$A$1826, A30) -> 2 | V30: =TEXTJOIN("|",FALSE, A30:T30) -> C01188|Vikram Reddy|24|East|Guwahati|Basic|Facebook|3/14/2023|33|Quarterly|Debit Card|875|4|0|27.30|3|6/18/2023||Active|Collaboration | W30: =COUNTIF($V$2:$V$1826, V30) -> 1 | X30: =IFERROR(__xludf.DUMMYFUNCTION("COUNTUNIQUE(FILTER($B$2:$B$1826,$A$2:$A$1826=A30))"),2.0) -> 2
A31: C00461 | B31: Karan Nair | C31: 44 | D31: South | E31: Chennai | F31: Basic | G31: Instagram | H31: 45535 | I31: 40 | J31: Monthly | K31: Upi | L31: 536 | M31: 5 | N31: 1 | O31: 10.9 | P31: 3 | Q31: 46723 | R31: 45699 | S31: Churned | T31: Analytics | U31: =COUNTIF($A$2:$A$1826, A31) -> 2 | V31: =TEXTJOIN("|",FALSE, A31:T31) -> C00461|Karan Nair|44|South|Chennai|Basic|Instagram|8/31/2024|40|Monthly|Upi|536|5|1|10.90|3|12/2/2027|2/11/2025|Churned|Analytics | W31: =COUNTIF($V$2:$V$1826, V31) -> 1 | X31: =IFERROR(__xludf.DUMMYFUNCTION("COUNTUNIQUE(FILTER($B$2:$B$1826,$A$2:$A$1826=A31))"),2.0) -> 2
A32: C01538 | B32: Sneha Patel | C32: 48 | D32: North | E32: Lucknow | F32: Basic | G32: Youtube | H32: 45987 | I32: 34 | J32: Annual | K32: Debit Card | L32: 784 | M32: 1 | N32: 1 | O32: 23 | P32: 2.9 | Q32: 46245 | S32: Active | T32: Automation | U32: =COUNTIF($A$2:$A$1826, A32) -> 1 | V32: =TEXTJOIN("|",FALSE, A32:T32) -> C01538|Sneha Patel|48|North|Lucknow|Basic|Youtube|11/26/2025|34|Annual|Debit Card|784|1|1|23.00|2.9|8/11/2026||Active|Automation | W32: =COUNTIF($V$2:$V$1826, V32) -> 1 | X32: =IFERROR(__xludf.DUMMYFUNCTION("COUNTUNIQUE(FILTER($B$2:$B$1826,$A$2:$A$1826=A32))"),1.0) -> 1
A33: C01220 | B33: Sneha Nair | C33: 35 | D33: East | E33: Guwahati | F33: Standard | G33: Facebook | H33: 45595 | I33: 28 | J33: Monthly | K33: Debit Card | L33: 1455 | M33: 0 | N33: 4 | O33: 26.2 | P33: 4.3 | Q33: 45767 | R33: 30/12/2026 | S33: Churned | T33: Collaboration | U33: =COUNTIF($A$2:$A$1826, A33) -> 3 | V33: =TEXTJOIN("|",FALSE, A33:T33) -> C01220|Sneha Nair|35|East|Guwahati|Standard|Facebook|10/30/2024|28|Monthly|Debit Card|1,455|0|4|26.20|4.3|4/20/2025|30/12/2026|Churned|Collaboration | W33: =COUNTIF($V$2:$V$1826, V33) -> 1 | X33: =IFERROR(__xludf.DUMMYFUNCTION("COUNTUNIQUE(FILTER($B$2:$B$1826,$A$2:$A$1826=A33))"),3.0) -> 3
A34: C01569 | B34: Rahul Singh | C34: 43 | D34: West | E34: Pune | F34: Basic | G34: Google Ads | H34: 45147 | I34: 16 | J34: Annual | K34: Upi | L34: 662 | M34: 2 | N34: 2 | O34: 11.2 | P34: 2.3 | Q34: 45227 | S34: Active | T34: Cloud Storage | U34: =COUNTIF($A$2:$A$1826, A34) -> 4 | V34: =TEXTJOIN("|",FALSE, A34:T34) -> C01569|Rahul Singh|43|West|Pune|Basic|Google Ads|8/9/2023|16|Annual|Upi|662|2|2|11.20|2.3|10/28/2023||Active|Cloud Storage | W34: =COUNTIF($V$2:$V$1826, V34) -> 1 | X34: =IFERROR(__xludf.DUMMYFUNCTION("COUNTUNIQUE(FILTER($B$2:$B$1826,$A$2:$A$1826=A34))"),4.0) -> 4
A35: C00132 | B35: Meera Das | C35: 49 | D35: West | E35: Surat | F35: Basic | G35: Email | H35: 45413 | I35: 4 | J35: Monthly | K35: Credit Card | L35: 714 | M35: 2 | N35: 2 | O35: 10.9 | P35: 3.8 | Q35: 45428 | S35: Active | T35: Collaboration | U35: =COUNTIF($A$2:$A$1826, A35) -> 2 | V35: =TEXTJOIN("|",FALSE, A35:T35) -> C00132|Meera Das|49|West|Surat|Basic|Email|5/1/2024|4|Monthly|Credit Card|714|2|2|10.90|3.8|5/16/2024||Active|Collaboration | W35: =COUNTIF($V$2:$V$1826, V35) -> 1 | X35: =IFERROR(__xludf.DUMMYFUNCTION("COUNTUNIQUE(FILTER($B$2:$B$1826,$A$2:$A$1826=A35))"),2.0) -> 2
A36: C01544 | B36: Arun Das | C36: 40 | D36: West | E36: Surat | F36: Standard | G36: Facebook | H36: 45680 | I36: 39 | J36: Annual | K36: Debit Card | L36: 1223 | M36: 1 | N36: 4 | O36: 36.7 | P36: 4.6 | Q36: 46582 | R36: 13/11/2027 | S36: Churned | T36: Security | U36: =COUNTIF($A$2:$A$1826, A36) -> 2 | V36: =TEXTJOIN("|",FALSE, A36:T36) -> C01544|Arun Das|40|West|Surat|Standard|Facebook|1/23/2025|39|Annual|Debit Card|1,223|1|4|36.70|4.6|7/14/2027|13/11/2027|Churned|Security | W36: =COUNTIF($V$2:$V$1826, V36) -> 1 | X36: =IFERROR(__xludf.DUMMYFUNCTION("COUNTUNIQUE(FILTER($B$2:$B$1826,$A$2:$A$1826=A36))"),2.0) -> 2
A37: C01484 | B37: Karan Patel | C37: 48 | D37: South | E37: Kochi | F37: Premium | G37: Organic Search | H37: 45655 | I37: 2 | J37: Monthly | K37: Upi | L37: 3356 | M37: 4 | N37: 1 | O37: 49.5 | P37: 3.7 | Q37: 45668 | R37: 45690 | S37: Churned | T37: Collaboration | U37: =COUNTIF($A$2:$A$1826, A37) -> 3 | V37: =TEXTJOIN("|",FALSE, A37:T37) -> C01484|Karan Patel|48|South|Kochi|Premium|Organic Search|12/29/2024|2|Monthly|Upi|3,356|4|1|49.50|3.7|1/11/2025|2/2/2025|Churned|Collaboration | W37: =COUNTIF($V$2:$V$1826, V37) -> 1 | X37: =IFERROR(__xludf.DUMMYFUNCTION("COUNTUNIQUE(FILTER($B$2:$B$1826,$A$2:$A$1826=A37))"),3.0) -> 3
A38: C00777 | B38: Arun Kumar | C38: 41 | D38: East | E38: Bhubaneswar | F38: Standard | G38: Referral | H38: 45338 | I38: 18 | J38: Monthly | K38: Debit Card | L38: 1257 | M38: 2 | N38: 1 | O38: 24.1 | P38: 3.8 | Q38: 45431 | R38: 45968 | S38: Churned | T38: Analytics | U38: =COUNTIF($A$2:$A$1826, A38) -> 2 | V38: =TEXTJOIN("|",FALSE, A38:T38) -> C00777|Arun Kumar|41|East|Bhubaneswar|Standard|Referral|2/16/2024|18|Monthly|Debit Card|1,257|2|1|24.10|3.8|5/19/2024|11/7/2025|Churned|Analytics | W38: =COUNTIF($V$2:$V$1826, V38) -> 1 | X38: =IFERROR(__xludf.DUMMYFUNCTION("COUNTUNIQUE(FILTER($B$2:$B$1826,$A$2:$A$1826=A38))"),2.0) -> 2
A39: C01600 | B39: Meera Singh | C39: 48 | D39: North | E39: Delhi | F39: Premium | G39: Instagram | H39: 44603 | I39: 40 | J39: Annual | K39: Credit Card | L39: 3370 | M39: 2 | N39: 1 | O39: 30.9 | P39: 3.4 | Q39: 44847 | S39: Active | T39: Collaboration | U39: =COUNTIF($A$2:$A$1826, A39) -> 1 | V39: =TEXTJOIN("|",FALSE, A39:T39) -> C01600|Meera Singh|48|North|Delhi|Premium|Instagram|2/11/2022|40|Annual|Credit Card|3,370|2|1|30.90|3.4|10/13/2022||Active|Collaboration | W39: =COUNTIF($V$2:$V$1826, V39) -> 1 | X39: =IFERROR(__xludf.DUMMYFUNCTION("COUNTUNIQUE(FILTER($B$2:$B$1826,$A$2:$A$1826=A39))"),1.0) -> 1
A40: C00344 | B40: Neha Sharma | C40: 56 | D40: North | E40: Jaipur | F40: Premium | G40: Google Ads | H40: 45747 | I40: 2 | J40: Annual | K40: Debit Card | L40: 3858 | M40: 4 | N40: 0 | O40: 38.4 | P40: 3.1 | Q40: 45805 | R40: 25/05/2025 | S40: Churned | T40: Cloud Storage | U40: =COUNTIF($A$2:$A$1826, A40) -> 2 | V40: =TEXTJOIN("|",FALSE, A40:T40) -> C00344|Neha Sharma|56|North|Jaipur|Premium|Google Ads|3/31/2025|2|Annual|Debit Card|3,858|4|0|38.40|3.1|5/28/2025|25/05/2025|Churned|Cloud Storage | W40: =COUNTIF($V$2:$V$1826, V40) -> 1 | X40: =IFERROR(__xludf.DUMMYFUNCTION("COUNTUNIQUE(FILTER($B$2:$B$1826,$A$2:$A$1826=A40))"),2.0) -> 2
...

Sheet Cleaned_Data
A1: Customer_ID | B1: Customer_Name | C1: Age | D1: Region | E1: City | F1: Plan | G1: Acquisition_Channel | H1: Signup_Date | I1: Tenure_Months | J1: Contract_Type | K1: Payment_Method | L1: Monthly_Fee | M1: Support_Tickets | N1: Complaints | O1: Monthly_Usage_Hours | P1: Satisfaction_Score | Q1: Last_Login | R1: Churn_Date | S1: Churn_Status | T1: Primary_Product | U1: Satisfaction_Group | V1: Usage_Group | W1: Tenure_Group
A2: C01310 | B2: Meera Das | D2: North | E2: Delhi | F2: Standard | G2: Instagram | H2: 45019 | I2: 9 | J2: Monthly | K2: Upi | L2: 1757 | M2: 2 | N2: 0 | O2: 32 | P2: 3.6 | Q2: 45308 | R2: 16/06/2023 | S2: Churned | T2: Cloud Storage | U2: =IF(P2="","",IFS(P2<3,"Low",P2<5,"Moderate",P2<7,"High",P2<=9,"Very High",TRUE,"Check Score")) -> Moderate | V2: =IF(O2="","",IF(O2<24, "Below Median", "Median or Above")) -> Median or Above | W2: =IF(I2="","",IFS(I2<0,"Invalid Tenure",I2<=12,"0–12 Months",I2<=24,"13–24 Months",I2<=48,"25–48 Months",TRUE,"49+ Months")) -> 0–12 Months
A3: C00477 | B3: Rahul Das | C3: 40 | D3: North | E3: Jaipur | F3: Standard | G3: Facebook | H3: 45678 | I3: 27 | J3: Quarterly | K3: Upi | L3: 1283 | M3: 0 | N3: 2 | O3: 40.6 | P3: 4.4 | Q3: 45694 | S3: Active | T3: Cloud Storage | U3: =IF(P3="","",IFS(P3<3,"Low",P3<5,"Moderate",P3<7,"High",P3<=9,"Very High",TRUE,"Check Score")) -> Moderate | V3: =IF(O3="","",IF(O3<24, "Below Median", "Median or Above")) -> Median or Above | W3: =IF(I3="","",IFS(I3<0,"Invalid Tenure",I3<=12,"0–12 Months",I3<=24,"13–24 Months",I3<=48,"25–48 Months",TRUE,"49+ Months")) -> 25–48 Months
A4: C01564 | B4: Priya Das | C4: 24 | D4: East | E4: Kolkata | F4: Basic | G4: Google Ads | H4: 45297 | I4: 23 | J4: Annual | K4: Credit Card | L4: 521 | M4: 2 | N4: 0 | O4: 14.3 | P4: 3.3 | Q4: 45856 | S4: Active | T4: Automation | U4: =IF(P4="","",IFS(P4<3,"Low",P4<5,"Moderate",P4<7,"High",P4<=9,"Very High",TRUE,"Check Score")) -> Moderate | V4: =IF(O4="","",IF(O4<24, "Below Median", "Median or Above")) -> Below Median | W4: =IF(I4="","",IFS(I4<0,"Invalid Tenure",I4<=12,"0–12 Months",I4<=24,"13–24 Months",I4<=48,"25–48 Months",TRUE,"49+ Months")) -> 13–24 Months
A5: C00741 | B5: Anita Patel | C5: 42 | D5: South | E5: Bengaluru | F5: Basic | G5: Instagram | H5: 45154 | I5: 6 | J5: Quarterly | K5: Upi | L5: 550 | M5: 1 | N5: 1 | O5: 9.9 | P5: 4 | Q5: 45280 | R5: 24/02/2024 | S5: Churned | T5: Collaboration | U5: =IF(P5="","",IFS(P5<3,"Low",P5<5,"Moderate",P5<7,"High",P5<=9,"Very High",TRUE,"Check Score")) -> Moderate | V5: =IF(O5="","",IF(O5<24, "Below Median", "Median or Above")) -> Below Median | W5: =IF(I5="","",IFS(I5<0,"Invalid Tenure",I5<=12,"0–12 Months",I5<=24,"13–24 Months",I5<=48,"25–48 Months",TRUE,"49+ Months")) -> 0–12 Months
A6: C01438 | B6: Anita Kumar | C6: 33 | D6: North | E6: Jaipur | F6: Standard | G6: Instagram | H6: 44896 | I6: 30 | J6: Monthly | K6: Credit Card | L6: 1703 | M6: 1 | N6: 1 | O6: 28.5 | P6: 2.4 | Q6: 45130 | S6: Active | T6: Security | U6: =IF(P6="","",IFS(P6<3,"Low",P6<5,"Moderate",P6<7,"High",P6<=9,"Very High",TRUE,"Check Score")) -> Low | V6: =IF(O6="","",IF(O6<24, "Below Median", "Median or Above")) -> Median or Above | W6: =IF(I6="","",IFS(I6<0,"Invalid Tenure",I6<=12,"0–12 Months",I6<=24,"13–24 Months",I6<=48,"25–48 Months",TRUE,"49+ Months")) -> 25–48 Months
A7: C00549 | B7: Vikram Patel | C7: 34 | D7: North | E7: Jaipur | F7: Premium | G7: Organic Search | H7: 45206 | I7: 14 | J7: Annual | K7: Debit Card | L7: 2938 | M7: 2 | N7: 1 | O7: 33.2 | P7: 3.4 | Q7: 45289 | S7: Active | T7: Automation | U7: =IF(P7="","",IFS(P7<3,"Low",P7<5,"Moderate",P7<7,"High",P7<=9,"Very High",TRUE,"Check Score")) -> Moderate | V7: =IF(O7="","",IF(O7<24, "Below Median", "Median or Above")) -> Median or Above | W7: =IF(I7="","",IFS(I7<0,"Invalid Tenure",I7<=12,"0–12 Months",I7<=24,"13–24 Months",I7<=48,"25–48 Months",TRUE,"49+ Months")) -> 13–24 Months
A8: C00539 | B8: Rahul Das | C8: 57 | D8: West | E8: Surat | F8: Basic | G8: Instagram | H8: 45605 | I8: 32 | J8: Monthly | K8: Credit Card | L8: 523 | M8: 2 | N8: 1 | O8: 16.2 | P8: 4.1 | Q8: 46257 | S8: Active | T8: Security | U8: =IF(P8="","",IFS(P8<3,"Low",P8<5,"Moderate",P8<7,"High",P8<=9,"Very High",TRUE,"Check Score")) -> Moderate | V8: =IF(O8="","",IF(O8<24, "Below Median", "Median or Above")) -> Below Median | W8: =IF(I8="","",IFS(I8<0,"Invalid Tenure",I8<=12,"0–12 Months",I8<=24,"13–24 Months",I8<=48,"25–48 Months",TRUE,"49+ Months")) -> 25–48 Months
A9: C01221 | B9: Anita Sharma | C9: 37 | D9: West | E9: Ahmedabad | F9: Premium | G9: Youtube | H9: 44585 | I9: 44 | J9: Quarterly | K9: Upi | L9: 3536 | M9: 0 | N9: 0 | O9: 43.9 | P9: 3.9 | Q9: 45141 | R9: 27/09/2025 | S9: Churned | T9: Security | U9: =IF(P9="","",IFS(P9<3,"Low",P9<5,"Moderate",P9<7,"High",P9<=9,"Very High",TRUE,"Check Score")) -> Moderate | V9: =IF(O9="","",IF(O9<24, "Below Median", "Median or Above")) -> Median or Above | W9: =IF(I9="","",IFS(I9<0,"Invalid Tenure",I9<=12,"0–12 Months",I9<=24,"13–24 Months",I9<=48,"25–48 Months",TRUE,"49+ Months")) -> 25–48 Months
A10: C00007 | B10: Rahul Kumar | C10: 57 | D10: East | E10: Bhubaneswar | F10: Standard | G10: Google Ads | H10: 45842 | I10: 20 | J10: Quarterly | K10: Credit Card | L10: 1622 | M10: 1 | N10: 1 | O10: 27.1 | P10: 3.4 | Q10: 46008 | R10: 20/08/2026 | S10: Churned | T10: Analytics | U10: =IF(P10="","",IFS(P10<3,"Low",P10<5,"Moderate",P10<7,"High",P10<=9,"Very High",TRUE,"Check Score")) -> Moderate | V10: =IF(O10="","",IF(O10<24, "Below Median", "Median or Above")) -> Median or Above | W10: =IF(I10="","",IFS(I10<0,"Invalid Tenure",I10<=12,"0–12 Months",I10<=24,"13–24 Months",I10<=48,"25–48 Months",TRUE,"49+ Months")) -> 13–24 Months
A11: C00230 | B11: Rahul Patel | C11: 61 | D11: East | E11: Patna | F11: Basic | G11: Instagram | H11: 45723 | I11: 6 | J11: Quarterly | K11: Debit Card | L11: 747 | M11: 1 | N11: 0 | O11: 20.7 | P11: 2.1 | Q11: 45869 | S11: Active | T11: Cloud Storage | U11: =IF(P11="","",IFS(P11<3,"Low",P11<5,"Moderate",P11<7,"High",P11<=9,"Very High",TRUE,"Check Score")) -> Low | V11: =IF(O11="","",IF(O11<24, "Below Median", "Median or Above")) -> Below Median | W11: =IF(I11="","",IFS(I11<0,"Invalid Tenure",I11<=12,"0–12 Months",I11<=24,"13–24 Months",I11<=48,"25–48 Months",TRUE,"49+ Months")) -> 0–12 Months
A12: C00543 | B12: Sneha Nair | C12: 26 | D12: West | E12: Pune | F12: Premium | G12: Youtube | H12: 45974 | I12: 13 | J12: Monthly | K12: Upi | L12: 3329 | M12: 2 | N12: 0 | O12: 42.7 | P12: 4.5 | Q12: 46175 | S12: Active | T12: Analytics | U12: =IF(P12="","",IFS(P12<3,"Low",P12<5,"Moderate",P12<7,"High",P12<=9,"Very High",TRUE,"Check Score")) -> Moderate | V12: =IF(O12="","",IF(O12<24, "Below Median", "Median or Above")) -> Median or Above | W12: =IF(I12="","",IFS(I12<0,"Invalid Tenure",I12<=12,"0–12 Months",I12<=24,"13–24 Months",I12<=48,"25–48 Months",TRUE,"49+ Months")) -> 13–24 Months
A13: C00693 | B13: Anita Sharma | C13: 51 | D13: North | E13: Jaipur | F13: Standard | G13: Google Ads | H13: 44707 | I13: 46 | J13: Monthly | K13: Credit Card | L13: 1068 | M13: 0 | N13: 0 | O13: 15.9 | P13: 4.7 | Q13: 44781 | S13: Active | T13: Security | U13: =IF(P13="","",IFS(P13<3,"Low",P13<5,"Moderate",P13<7,"High",P13<=9,"Very High",TRUE,"Check Score")) -> Moderate | V13: =IF(O13="","",IF(O13<24, "Below Median", "Median or Above")) -> Below Median | W13: =IF(I13="","",IFS(I13<0,"Invalid Tenure",I13<=12,"0–12 Months",I13<=24,"13–24 Months",I13<=48,"25–48 Months",TRUE,"49+ Months")) -> 25–48 Months
A14: C00439 | B14: Karan Nair | C14: 65 | D14: South | E14: Kochi | F14: Basic | G14: Email | H14: 45395 | I14: 13 | J14: Monthly | K14: Debit Card | L14: 836 | M14: 3 | N14: 2 | O14: 27.4 | Q14: 45621 | S14: Active | T14: Analytics | U14: =IF(P14="","",IFS(P14<3,"Low",P14<5,"Moderate",P14<7,"High",P14<=9,"Very High",TRUE,"Check Score")) | V14: =IF(O14="","",IF(O14<24, "Below Median", "Median or Above")) -> Median or Above | W14: =IF(I14="","",IFS(I14<0,"Invalid Tenure",I14<=12,"0–12 Months",I14<=24,"13–24 Months",I14<=48,"25–48 Months",TRUE,"49+ Months")) -> 13–24 Months
A15: C00125 | B15: Vikram Nair | C15: 34 | D15: West | E15: Ahmedabad | F15: Standard | G15: Google Ads | H15: 45071 | I15: 13 | J15: Monthly | K15: Credit Card | L15: 1142 | M15: 2 | N15: 0 | O15: 27.7 | P15: 5 | Q15: 45174 | S15: Active | T15: Automation | U15: =IF(P15="","",IFS(P15<3,"Low",P15<5,"Moderate",P15<7,"High",P15<=9,"Very High",TRUE,"Check Score")) -> High | V15: =IF(O15="","",IF(O15<24, "Below Median", "Median or Above")) -> Median or Above | W15: =IF(I15="","",IFS(I15<0,"Invalid Tenure",I15<=12,"0–12 Months",I15<=24,"13–24 Months",I15<=48,"25–48 Months",TRUE,"49+ Months")) -> 13–24 Months
A16: C00201 | B16: Arun Patel | C16: 43 | D16: North | E16: Delhi | F16: Premium | G16: Youtube | H16: 45046 | I16: 11 | J16: Monthly | K16: Credit Card | L16: 3769 | M16: 3 | N16: 1 | O16: 38.7 | P16: 3.4 | Q16: 45261 | S16: Active | T16: Collaboration | U16: =IF(P16="","",IFS(P16<3,"Low",P16<5,"Moderate",P16<7,"High",P16<=9,"Very High",TRUE,"Check Score")) -> Moderate | V16: =IF(O16="","",IF(O16<24, "Below Median", "Median or Above")) -> Median or Above | W16: =IF(I16="","",IFS(I16<0,"Invalid Tenure",I16<=12,"0–12 Months",I16<=24,"13–24 Months",I16<=48,"25–48 Months",TRUE,"49+ Months")) -> 0–12 Months
A17: C00932 | B17: Arun Kumar | C17: 66 | D17: East | E17: Guwahati | F17: Standard | G17: Facebook | H17: 45700 | I17: 43 | J17: Quarterly | K17: Upi | L17: 1193 | M17: 5 | N17: 3 | O17: 21.5 | P17: 3.2 | Q17: 46155 | S17: Active | T17: Analytics | U17: =IF(P17="","",IFS(P17<3,"Low",P17<5,"Moderate",P17<7,"High",P17<=9,"Very High",TRUE,"Check Score")) -> Moderate | V17: =IF(O17="","",IF(O17<24, "Below Median", "Median or Above")) -> Below Median | W17: =IF(I17="","",IFS(I17<0,"Invalid Tenure",I17<=12,"0–12 Months",I17<=24,"13–24 Months",I17<=48,"25–48 Months",TRUE,"49+ Months")) -> 25–48 Months
A18: C01197 | B18: Karan Sharma | C18: 55 | D18: West | E18: Pune | F18: Basic | G18: Organic Search | H18: 44726 | I18: 12 | J18: Monthly | K18: Debit Card | L18: 533 | M18: 1 | N18: 2 | O18: 12.4 | P18: 3.4 | Q18: 44856 | S18: Active | T18: Automation | U18: =IF(P18="","",IFS(P18<3,"Low",P18<5,"Moderate",P18<7,"High",P18<=9,"Very High",TRUE,"Check Score")) -> Moderate | V18: =IF(O18="","",IF(O18<24, "Below Median", "Median or Above")) -> Below Median | W18: =IF(I18="","",IFS(I18<0,"Invalid Tenure",I18<=12,"0–12 Months",I18<=24,"13–24 Months",I18<=48,"25–48 Months",TRUE,"49+ Months")) -> 0–12 Months
A19: C00082 | B19: Vikram Das | C19: 27 | D19: North | E19: Lucknow | F19: Standard | G19: Organic Search | H19: 45632 | I19: 21 | J19: Annual | K19: Debit Card | L19: 1684 | M19: 1 | N19: 0 | O19: 6.8 | P19: 4 | Q19: 45963 | R19: 45817 | S19: Churned | T19: Collaboration | U19: =IF(P19="","",IFS(P19<3,"Low",P19<5,"Moderate",P19<7,"High",P19<=9,"Very High",TRUE,"Check Score")) -> Moderate | V19: =IF(O19="","",IF(O19<24, "Below Median", "Median or Above")) -> Below Median | W19: =IF(I19="","",IFS(I19<0,"Invalid Tenure",I19<=12,"0–12 Months",I19<=24,"13–24 Months",I19<=48,"25–48 Months",TRUE,"49+ Months")) -> 13–24 Months
A20: C00937 | B20: Anita Sharma | C20: 34 | D20: East | E20: Kolkata | F20: Basic | G20: Organic Search | H20: 45715 | I20: 7 | J20: Quarterly | K20: Credit Card | L20: 608 | M20: 2 | N20: 2 | O20: 16.7 | P20: 4.1 | Q20: 45758 | S20: Active | T20: Cloud Storage | U20: =IF(P20="","",IFS(P20<3,"Low",P20<5,"Moderate",P20<7,"High",P20<=9,"Very High",TRUE,"Check Score")) -> Moderate | V20: =IF(O20="","",IF(O20<24, "Below Median", "Median or Above")) -> Below Median | W20: =IF(I20="","",IFS(I20<0,"Invalid Tenure",I20<=12,"0–12 Months",I20<=24,"13–24 Months",I20<=48,"25–48 Months",TRUE,"49+ Months")) -> 0–12 Months
A21: C00898 | B21: Ravi Patel | C21: 36 | D21: East | E21: Kolkata | F21: Standard | G21: Organic Search | H21: 45175 | I21: 43 | J21: Monthly | K21: Debit Card | L21: 1269 | M21: 1 | N21: 1 | O21: 12.6 | P21: 3.7 | Q21: 45404 | S21: Active | T21: Cloud Storage | U21: =IF(P21="","",IFS(P21<3,"Low",P21<5,"Moderate",P21<7,"High",P21<=9,"Very High",TRUE,"Check Score")) -> Moderate | V21: =IF(O21="","",IF(O21<24, "Below Median", "Median or Above")) -> Below Median | W21: =IF(I21="","",IFS(I21<0,"Invalid Tenure",I21<=12,"0–12 Months",I21<=24,"13–24 Months",I21<=48,"25–48 Months",TRUE,"49+ Months")) -> 25–48 Months
A22: C01470 | B22: Vikram Kumar | C22: 19 | D22: East | E22: Bhubaneswar | F22: Standard | G22: Youtube | H22: 45102 | I22: 33 | J22: Quarterly | K22: Upi | L22: 1093 | M22: 1 | N22: 1 | O22: 26.5 | P22: 4 | Q22: 45545 | S22: Active | T22: Collaboration | U22: =IF(P22="","",IFS(P22<3,"Low",P22<5,"Moderate",P22<7,"High",P22<=9,"Very High",TRUE,"Check Score")) -> Moderate | V22: =IF(O22="","",IF(O22<24, "Below Median", "Median or Above")) -> Median or Above | W22: =IF(I22="","",IFS(I22<0,"Invalid Tenure",I22<=12,"0–12 Months",I22<=24,"13–24 Months",I22<=48,"25–48 Months",TRUE,"49+ Months")) -> 25–48 Months
A23: C00331 | B23: Ravi Patel | C23: 46 | D23: West | E23: Surat | F23: Standard | G23: Google Ads | H23: 44716 | I23: 45 | J23: Monthly | K23: Upi | L23: 1035 | M23: 2 | N23: 2 | O23: 37.1 | P23: 4.4 | Q23: 45482 | R23: 45879 | S23: Churned | T23: Collaboration | U23: =IF(P23="","",IFS(P23<3,"Low",P23<5,"Moderate",P23<7,"High",P23<=9,"Very High",TRUE,"Check Score")) -> Moderate | V23: =IF(O23="","",IF(O23<24, "Below Median", "Median or Above")) -> Median or Above | W23: =IF(I23="","",IFS(I23<0,"Invalid Tenure",I23<=12,"0–12 Months",I23<=24,"13–24 Months",I23<=48,"25–48 Months",TRUE,"49+ Months")) -> 25–48 Months
A24: C00747 | B24: Rahul Singh | C24: 29 | D24: North | E24: Chandigarh | F24: Basic | G24: Instagram | H24: 45927 | I24: 7 | J24: Monthly | K24: Credit Card | L24: 785 | M24: 0 | N24: 2 | O24: 10.1 | P24: 3.2 | Q24: 46095 | S24: Active | T24: Analytics | U24: =IF(P24="","",IFS(P24<3,"Low",P24<5,"Moderate",P24<7,"High",P24<=9,"Very High",TRUE,"Check Score")) -> Moderate | V24: =IF(O24="","",IF(O24<24, "Below Median", "Median or Above")) -> Below Median | W24: =IF(I24="","",IFS(I24<0,"Invalid Tenure",I24<=12,"0–12 Months",I24<=24,"13–24 Months",I24<=48,"25–48 Months",TRUE,"49+ Months")) -> 0–12 Months
A25: C00368 | B25: Sneha Singh | C25: 31 | D25: East | E25: Guwahati | F25: Standard | G25: Youtube | H25: 45070 | I25: 18 | J25: Quarterly | K25: Credit Card | L25: 1109 | M25: 1 | N25: 1 | O25: 15.6 | P25: 3.8 | Q25: 45119 | S25: Active | T25: Collaboration | U25: =IF(P25="","",IFS(P25<3,"Low",P25<5,"Moderate",P25<7,"High",P25<=9,"Very High",TRUE,"Check Score")) -> Moderate | V25: =IF(O25="","",IF(O25<24, "Below Median", "Median or Above")) -> Below Median | W25: =IF(I25="","",IFS(I25<0,"Invalid Tenure",I25<=12,"0–12 Months",I25<=24,"13–24 Months",I25<=48,"25–48 Months",TRUE,"49+ Months")) -> 13–24 Months
A26: C00467 | B26: Ravi Reddy | C26: 20 | D26: South | E26: Bengaluru | F26: Standard | G26: Email | H26: 45234 | I26: 18 | J26: Monthly | K26: Credit Card | L26: 1284 | M26: 4 | N26: 1 | O26: 21.7 | P26: 3.4 | Q26: 45765 | R26: 16/01/2025 | S26: Churned | T26: Cloud Storage | U26: =IF(P26="","",IFS(P26<3,"Low",P26<5,"Moderate",P26<7,"High",P26<=9,"Very High",TRUE,"Check Score")) -> Moderate | V26: =IF(O26="","",IF(O26<24, "Below Median", "Median or Above")) -> Below Median | W26: =IF(I26="","",IFS(I26<0,"Invalid Tenure",I26<=12,"0–12 Months",I26<=24,"13–24 Months",I26<=48,"25–48 Months",TRUE,"49+ Months")) -> 13–24 Months
A27: C01190 | B27: Meera Singh | C27: 35 | D27: East | E27: Kolkata | F27: Basic | G27: Email | H27: 45269 | I27: 47 | J27: Monthly | K27: Debit Card | L27: 722 | N27: 4 | O27: 15.4 | P27: 3.5 | Q27: 45515 | R27: 46176 | S27: Churned | T27: Security | U27: =IF(P27="","",IFS(P27<3,"Low",P27<5,"Moderate",P27<7,"High",P27<=9,"Very High",TRUE,"Check Score")) -> Moderate | V27: =IF(O27="","",IF(O27<24, "Below Median", "Median or Above")) -> Below Median | W27: =IF(I27="","",IFS(I27<0,"Invalid Tenure",I27<=12,"0–12 Months",I27<=24,"13–24 Months",I27<=48,"25–48 Months",TRUE,"49+ Months")) -> 25–48 Months
A28: C00004 | B28: Ravi Iyer | C28: 61 | D28: South | E28: Hyderabad | F28: Basic | G28: Facebook | H28: 45238 | I28: 40 | J28: Quarterly | K28: Credit Card | L28: 562 | M28: 0 | N28: 0 | O28: 19.8 | P28: 4.5 | Q28: 45863 | S28: Active | T28: Security | U28: =IF(P28="","",IFS(P28<3,"Low",P28<5,"Moderate",P28<7,"High",P28<=9,"Very High",TRUE,"Check Score")) -> Moderate | V28: =IF(O28="","",IF(O28<24, "Below Median", "Median or Above")) -> Below Median | W28: =IF(I28="","",IFS(I28<0,"Invalid Tenure",I28<=12,"0–12 Months",I28<=24,"13–24 Months",I28<=48,"25–48 Months",TRUE,"49+ Months")) -> 25–48 Months
A29: C01428 | B29: Ravi Kumar | C29: 38 | D29: East | E29: Bhubaneswar | F29: Basic | G29: Facebook | H29: 45338 | I29: 44 | J29: Quarterly | K29: Upi | L29: 588 | M29: 2 | N29: 1 | O29: 19.4 | P29: 2.6 | Q29: 45964 | R29: 26/06/2026 | S29: Churned | T29: Security | U29: =IF(P29="","",IFS(P29<3,"Low",P29<5,"Moderate",P29<7,"High",P29<=9,"Very High",TRUE,"Check Score")) -> Low | V29: =IF(O29="","",IF(O29<24, "Below Median", "Median or Above")) -> Below Median | W29: =IF(I29="","",IFS(I29<0,"Invalid Tenure",I29<=12,"0–12 Months",I29<=24,"13–24 Months",I29<=48,"25–48 Months",TRUE,"49+ Months")) -> 25–48 Months
A30: C01188 | B30: Vikram Reddy | C30: 24 | D30: East | E30: Guwahati | F30: Basic | G30: Facebook | H30: 44999 | I30: 33 | J30: Quarterly | K30: Debit Card | L30: 875 | M30: 4 | N30: 0 | O30: 27.3 | P30: 3 | Q30: 45095 | S30: Active | T30: Collaboration | U30: =IF(P30="","",IFS(P30<3,"Low",P30<5,"Moderate",P30<7,"High",P30<=9,"Very High",TRUE,"Check Score")) -> Moderate | V30: =IF(O30="","",IF(O30<24, "Below Median", "Median or Above")) -> Median or Above | W30: =IF(I30="","",IFS(I30<0,"Invalid Tenure",I30<=12,"0–12 Months",I30<=24,"13–24 Months",I30<=48,"25–48 Months",TRUE,"49+ Months")) -> 25–48 Months
A31: C00461 | B31: Karan Nair | C31: 44 | D31: South | E31: Chennai | F31: Basic | G31: Instagram | H31: 45535 | I31: 40 | J31: Monthly | K31: Upi | L31: 536 | M31: 5 | N31: 1 | O31: 10.9 | P31: 3 | Q31: 46723 | R31: 45699 | S31: Churned | T31: Analytics | U31: =IF(P31="","",IFS(P31<3,"Low",P31<5,"Moderate",P31<7,"High",P31<=9,"Very High",TRUE,"Check Score")) -> Moderate | V31: =IF(O31="","",IF(O31<24, "Below Median", "Median or Above")) -> Below Median | W31: =IF(I31="","",IFS(I31<0,"Invalid Tenure",I31<=12,"0–12 Months",I31<=24,"13–24 Months",I31<=48,"25–48 Months",TRUE,"49+ Months")) -> 25–48 Months
A32: C01538 | B32: Sneha Patel | C32: 48 | D32: North | E32: Lucknow | F32: Basic | G32: Youtube | H32: 45987 | I32: 34 | J32: Annual | K32: Debit Card | L32: 784 | M32: 1 | N32: 1 | O32: 23 | P32: 2.9 | Q32: 46245 | S32: Active | T32: Automation | U32: =IF(P32="","",IFS(P32<3,"Low",P32<5,"Moderate",P32<7,"High",P32<=9,"Very High",TRUE,"Check Score")) -> Low | V32: =IF(O32="","",IF(O32<24, "Below Median", "Median or Above")) -> Below Median | W32: =IF(I32="","",IFS(I32<0,"Invalid Tenure",I32<=12,"0–12 Months",I32<=24,"13–24 Months",I32<=48,"25–48 Months",TRUE,"49+ Months")) -> 25–48 Months
A33: C01220 | B33: Sneha Nair | C33: 35 | D33: East | E33: Guwahati | F33: Standard | G33: Facebook | H33: 45595 | I33: 28 | J33: Monthly | K33: Debit Card | L33: 1455 | M33: 0 | N33: 4 | O33: 26.2 | P33: 4.3 | Q33: 45767 | R33: 30/12/2026 | S33: Churned | T33: Collaboration | U33: =IF(P33="","",IFS(P33<3,"Low",P33<5,"Moderate",P33<7,"High",P33<=9,"Very High",TRUE,"Check Score")) -> Moderate | V33: =IF(O33="","",IF(O33<24, "Below Median", "Median or Above")) -> Median or Above | W33: =IF(I33="","",IFS(I33<0,"Invalid Tenure",I33<=12,"0–12 Months",I33<=24,"13–24 Months",I33<=48,"25–48 Months",TRUE,"49+ Months")) -> 25–48 Months
A34: C01569 | B34: Rahul Singh | C34: 43 | D34: West | E34: Pune | F34: Basic | G34: Google Ads | H34: 45147 | I34: 16 | J34: Annual | K34: Upi | L34: 662 | M34: 2 | N34: 2 | O34: 11.2 | P34: 2.3 | Q34: 45227 | S34: Active | T34: Cloud Storage | U34: =IF(P34="","",IFS(P34<3,"Low",P34<5,"Moderate",P34<7,"High",P34<=9,"Very High",TRUE,"Check Score")) -> Low | V34: =IF(O34="","",IF(O34<24, "Below Median", "Median or Above")) -> Below Median | W34: =IF(I34="","",IFS(I34<0,"Invalid Tenure",I34<=12,"0–12 Months",I34<=24,"13–24 Months",I34<=48,"25–48 Months",TRUE,"49+ Months")) -> 13–24 Months
A35: C00132 | B35: Meera Das | C35: 49 | D35: West | E35: Surat | F35: Basic | G35: Email | H35: 45413 | I35: 4 | J35: Monthly | K35: Credit Card | L35: 714 | M35: 2 | N35: 2 | O35: 10.9 | P35: 3.8 | Q35: 45428 | S35: Active | T35: Collaboration | U35: =IF(P35="","",IFS(P35<3,"Low",P35<5,"Moderate",P35<7,"High",P35<=9,"Very High",TRUE,"Check Score")) -> Moderate | V35: =IF(O35="","",IF(O35<24, "Below Median", "Median or Above")) -> Below Median | W35: =IF(I35="","",IFS(I35<0,"Invalid Tenure",I35<=12,"0–12 Months",I35<=24,"13–24 Months",I35<=48,"25–48 Months",TRUE,"49+ Months")) -> 0–12 Months
A36: C01544 | B36: Arun Das | C36: 40 | D36: West | E36: Surat | F36: Standard | G36: Facebook | H36: 45680 | I36: 39 | J36: Annual | K36: Debit Card | L36: 1223 | M36: 1 | N36: 4 | O36: 36.7 | P36: 4.6 | Q36: 46582 | R36: 13/11/2027 | S36: Churned | T36: Security | U36: =IF(P36="","",IFS(P36<3,"Low",P36<5,"Moderate",P36<7,"High",P36<=9,"Very High",TRUE,"Check Score")) -> Moderate | V36: =IF(O36="","",IF(O36<24, "Below Median", "Median or Above")) -> Median or Above | W36: =IF(I36="","",IFS(I36<0,"Invalid Tenure",I36<=12,"0–12 Months",I36<=24,"13–24 Months",I36<=48,"25–48 Months",TRUE,"49+ Months")) -> 25–48 Months
A37: C01484 | B37: Karan Patel | C37: 48 | D37: South | E37: Kochi | F37: Premium | G37: Organic Search | H37: 45655 | I37: 2 | J37: Monthly | K37: Upi | L37: 3356 | M37: 4 | N37: 1 | O37: 49.5 | P37: 3.7 | Q37: 45668 | R37: 45690 | S37: Churned | T37: Collaboration | U37: =IF(P37="","",IFS(P37<3,"Low",P37<5,"Moderate",P37<7,"High",P37<=9,"Very High",TRUE,"Check Score")) -> Moderate | V37: =IF(O37="","",IF(O37<24, "Below Median", "Median or Above")) -> Median or Above | W37: =IF(I37="","",IFS(I37<0,"Invalid Tenure",I37<=12,"0–12 Months",I37<=24,"13–24 Months",I37<=48,"25–48 Months",TRUE,"49+ Months")) -> 0–12 Months
A38: C00777 | B38: Arun Kumar | C38: 41 | D38: East | E38: Bhubaneswar | F38: Standard | G38: Referral | H38: 45338 | I38: 18 | J38: Monthly | K38: Debit Card | L38: 1257 | M38: 2 | N38: 1 | O38: 24.1 | P38: 3.8 | Q38: 45431 | R38: 45968 | S38: Churned | T38: Analytics | U38: =IF(P38="","",IFS(P38<3,"Low",P38<5,"Moderate",P38<7,"High",P38<=9,"Very High",TRUE,"Check Score")) -> Moderate | V38: =IF(O38="","",IF(O38<24, "Below Median", "Median or Above")) -> Median or Above | W38: =IF(I38="","",IFS(I38<0,"Invalid Tenure",I38<=12,"0–12 Months",I38<=24,"13–24 Months",I38<=48,"25–48 Months",TRUE,"49+ Months")) -> 13–24 Months
A39: C01600 | B39: Meera Singh | C39: 48 | D39: North | E39: Delhi | F39: Premium | G39: Instagram | H39: 44603 | I39: 40 | J39: Annual | K39: Credit Card | L39: 3370 | M39: 2 | N39: 1 | O39: 30.9 | P39: 3.4 | Q39: 44847 | S39: Active | T39: Collaboration | U39: =IF(P39="","",IFS(P39<3,"Low",P39<5,"Moderate",P39<7,"High",P39<=9,"Very High",TRUE,"Check Score")) -> Moderate | V39: =IF(O39="","",IF(O39<24, "Below Median", "Median or Above")) -> Median or Above | W39: =IF(I39="","",IFS(I39<0,"Invalid Tenure",I39<=12,"0–12 Months",I39<=24,"13–24 Months",I39<=48,"25–48 Months",TRUE,"49+ Months")) -> 25–48 Months
